<?xml version="1.0" encoding="UTF-8"?>
<testsuite name="test_register_order_tests.MyTestCase-20230301175648" tests="1" file="test_register_order_tests.py" time="0.002" timestamp="2023-03-01T17:56:48" failures="1" errors="0" skipped="0">
	<testcase classname="test_register_order_tests.MyTestCase" name="test_something" time="0.002" timestamp="2023-03-01T17:56:48">
		<failure type="AssertionError" message="True != False"><![CDATA[Traceback (most recent call last):
  File "/Library/Frameworks/Python.framework/Versions/3.11/lib/python3.11/unittest/case.py", line 57, in testPartExecutor
    yield
  File "/Library/Frameworks/Python.framework/Versions/3.11/lib/python3.11/unittest/case.py", line 623, in run
    self._callTestMethod(testMethod)
    ^^^^^^^^^^^^^^^^^
  File "/Library/Frameworks/Python.framework/Versions/3.11/lib/python3.11/unittest/case.py", line 579, in _callTestMethod
    if method() is not None:
    ^^^^^^^^^^^^^^^^^
  File "/Users/edu/PycharmProjects/G89.2023.T20.EG3/src/unittest/python/test_register_order_tests.py", line 9, in test_something
    self.assertEqual(True, False)
    ^^^^^^^^^^^^^^^^^
  File "/Library/Frameworks/Python.framework/Versions/3.11/lib/python3.11/unittest/case.py", line 873, in assertEqual
    assertion_func(first, second, msg=msg)
    ^^^^^^^^^^^^^^^^^
  File "/Library/Frameworks/Python.framework/Versions/3.11/lib/python3.11/unittest/case.py", line 866, in _baseAssertEqual
    raise self.failureException(msg)
    ^^^^^^^^^^^^^^^^^
AssertionError: True != False
]]></failure>
	</testcase>
</testsuite>
